Workbook

Sheet Summary
A2: Count | B2: Module S/N | C2: Pedigree | D2: Manifold S/N | E2: GEN S/N | F2: GEN P/N SW | G2: GEN HW | H2: EDM S/N | I2: EDM P/N SW | J2: EDM HW | K2: BCP S/N | L2: BCP P/N SW | M2: BCP HW | N2: Allocation | O2: Allocation | P2: Allocation | Q2: Allocation | R2: Allocation
A3: 1 | B3: S003 | C3: 3D Printed | D3: 0 | E3: BMW pump | H3: 4230 Lucid | K3: 7269 Lucid
A4: 2 | B4: S004 | C4: 3D Printed | D4: 0 | E4: BMW pump | H4: 4241 Lucid | K4: 4242 Lucid
A5: 3 | B5: S005 | C5: 3D Printed | D5: PA 12 40% Glass Filled | E5: BMW pump | H5: 0016 Lucid | K5: 0026 Lucid
A6: 4 | B6: S006 | C6: 3D Printed | E6: BMW pump | H6: 7286 Lucid | K6: 4232 Lucid
A7: 5 | B7: S106 | C7: 3D Printed | E7: MeWP200W STLA-F TRIPUMP0005 | F7: ID # (PLUC431M1D0A-01) SW:B1C0 | G7: IC0 | H7: 09.06.2023MeWP 80W STLA-F TP EDM 0004 | I7: ID # (UC431M1D1B-01) SW B530 | K7: MeWP 80W STLA EVO BCP0007 | L7: ID # (UC431M1D2B-01 SW BC60)
A8: 6 | B8: S107 | C8: 3D Printed | E8: MeWP200W STLA-F TRIPUMP0012 | F8: ID # (PLUC431M1D0A-01) SW:B1C0 | G8: IC0 | H8: 09.06.2023MeWP 80W STLA-F TP EDM 0013 | I8: ID # (UC431M1D1B-01) SW B530 | K8: MeWP 80W STLA EVO BCP0008 | L8: ID # (UC431M1D2B-01 SW BC60)
A9: 7 | B9: S108 | C9: 3D Printed | E9: MeWP200W STLA-F TRIPUMP0008 | F9: ID # (PLUC431M1D0A-01) SW:B1C0 | G9: IC0 | H9: 09.06.2023MeWP 80W STLA-F TP EDM 0007 | I9: ID # (UC431M1D1B-01) SW B530 | K9: MeWP 80W STLA EVO BCP0013 | L9: ID # (UC431M1D2B-01 SW BC60)
A10: 8 | B10: S109 | C10: 3D Printed | E10: MeWP200W STLA-F TRIPUMP0007 | F10: ID # (PLUC431M1D0A-01) SW:B1C0 | G10: IC0 | H10: 09.06.2023MeWP 80W STLA-F TP EDM 0008 | I10: ID # (UC431M1D1B-01) SW B530 | K10: MeWP 80W STLA EVO BCP0006 | L10: ID # (UC431M1D2B-01 SW BC60)
A11: 9 | B11: S110 | C11: 3D Printed | E11: MeWP200W STLA-F TRIPUMP0011 | F11: ID # (PLUC431M1D0A-01) SW:B1C0 | G11: IC0 | H11: 09.06.2023MeWP 80W STLA-F TP EDM 0015 | I11: ID # (UC431M1D1B-01) SW B530 | K11: MeWP 80W STLA EVO BCP0014 | L11: ID # (UC431M1D2B-01 SW BC60)
A12: 10 | B12: S111 | C12: 3D Printed | E12: MeWP200W STLA-F TRIPUMP0014 | F12: ID # (PLUC431M1D0A-01) SW:B1C0 | G12: IC0 | H12: 09.06.2023MeWP 80W STLA-F TP EDM 0009 | I12: ID # (UC431M1D1B-01) SW B530 | K12: MeWP 80W STLA EVO BCP0010 | L12: ID # (UC431M1D2B-01 SW BC60)
A13: 11 | B13: S112 | C13: 3D Printed | E13: MeWP200W STLA-F TRIPUMP0013 | F13: ID # (PLUC431M1D0A-01) SW:B1C0 | G13: IC0 | H13: 09.06.2023MeWP 80W STLA-F TP EDM 0011 | I13: ID # (UC431M1D1B-01) SW B530 | K13: MeWP 80W STLA EVO BCP0015 | L13: ID # (UC431M1D2B-01 SW BC60)
A14: 12 | B14: S113 | C14: 3D Printed | E14: MeWP200W STLA-F TRIPUMP0028 | F14: ID # (PLUC431M1D0A-01) SW:B1C0 | G14: IC0 | H14: 21.06.2023MeWP 80W STLA-F TP EDM 0027 | I14: ID # (UC431M1D1B-01) SW B530 | K14: MeWP 80W STLA EVO BCP0018 | L14: ID # (UC431M1D2B-01 SW BC60)
A15: 13 | B15: S114 | C15: 3D Printed | E15: MeWP200W STLA-F TRIPUMP0031 | F15: ID # (PLUC431M1D0A-01) SW:B1C0 | G15: IC0 | H15: 21.06.2023MeWP 80W STLA-F TP EDM 0023 | I15: ID # (UC431M1D1B-01) SW B530 | K15: MeWP 80W STLA EVO BCP0019 | L15: ID # (UC431M1D2B-01 SW BC60)
A16: 14 | B16: S115 | C16: 3D Printed | E16: MeWP200W STLA-F TRIPUMP0029 | F16: ID # (PLUC431M1D0A-01) SW:B1C0 | G16: IC0 | H16: 21.06.2023MeWP 80W STLA-F TP EDM 0026 | I16: ID # (UC431M1D1B-01) SW B530 | K16: MeWP 80W STLA EVO BCP0024 | L16: ID # (UC431M1D2B-01 SW BC60)
A17: 15 | B17: S116 | C17: 3D Printed | E17: MeWP200W STLA-F TRIPUMP0033 | F17: ID # (PLUC431M1D0A-01) SW:B1C0 | G17: IC0 | H17: 21.06.2023MeWP 80W STLA-F TP EDM 0024 | I17: ID # (UC431M1D1B-01) SW B530 | K17: MeWP 80W STLA EVO BCP0021 | L17: ID # (UC431M1D2B-01 SW BC60)
A18: 16 | B18: S118 | C18: 3D Printed | E18: MeWP200W STLA-F TRIPUMP0037 | F18: ID # (PLUC431M1D0A-01) SW:B1C0 | G18: IC0 | H18: 21.06.2023MeWP 80W STLA-F TP EDM 0022 | I18: ID # (UC431M1D1B-01) SW B530 | K18: MeWP 80W STLA EVO BCP0020 | L18: ID # (UC431M1D2B-01 SW BC60)
... A22: 20 | B22: S202 | C22: Soft Tool | E22: MeWP200W STLA-F TRIPUMP0051 | F22: ID # (PLUC431M1D0A-01) SW:B1C0 | G22: IC0 | H22: 09.08.2023MeWP 80W STLA-F TP EDM0043 | I22: ID # (UC431M1D1B-01) SW B530 | K22: MeWP 80W STLA EVO BCP0033 | L22: ID # (UC431M1D2B-01 SW BC60)
A23: 21 | B23: S205 | C23: Soft Tool | E23: MeWP200W STLA-F TRIPUMP0050 | F23: ID # (PLUC431M1D0A-01) SW:B1C0 | G23: IC0 | H23: 09.08.2023MeWP 80W STLA-F TP EDM0042 | I23: ID # (UC431M1D1B-01) SW B530 | K23: MeWP 80W STLA EVO BCP0032 | L23: ID # (UC431M1D2B-01 SW BC60) | N23: Assigned to ALT -- TR.CC23.23033
A24: 22 | B24: S206 | C24: Soft Tool | E24: MeWP200W STLA-F TRIPUMP0049 | F24: ID # (PLUC431M1D0A-01) SW:B1C0 | G24: IC0 | H24: 09.08.2023MeWP 80W STLA-F TP EDM0041 | I24: ID # (UC431M1D1B-01) SW B530 | K24: MeWP 80W STLA EVO BCP0037 | L24: ID # (UC431M1D2B-01 SW BC60) | N24: Assigned to ALT -- TR.CC23.23033
A25: 23 | B25: S207 | C25: Soft Tool | D25: 8 | E25: MeWP200W STLA-F TRIPUMP0046 | F25: ID # (PLUC431M1D0A-01) SW:B1C0 | G25: IC0 | H25: 09.08.2023MeWP 80W STLA-F TP EDM0038 | I25: ID # (UC431M1D1B-01) SW B530 | K25: MeWP 80W STLA EVO BCP0039 | L25: ID # (UC431M1D2B-01 SW BC60)
A26: 24 | B26: S208 | C26: Soft Tool | D26: 11 | E26: MeWP200W STLA-F TRIPUMP0041 | F26: ID # (PLUC431M1D0A-01) SW:B1C0 | G26: IC0 | H26: 09.08.2023MeWP 80W STLA-F TP EDM0033 | I26: ID # (UC431M1D1B-01) SW B530 | K26: MeWP 80W STLA EVO BCP0034 | L26: ID # (UC431M1D2B-01 SW BC60)
A27: 25 | B27: S209 | C27: Soft Tool | D27: 4 | E27: MeWP200W STLA-F TRIPUMP0036 | F27: ID # (PLUC431M1D0A-01) SW:B1C0 | G27: IC0 | H27: 09.08.2023MeWP 80W STLA-F TP EDM0032 | I27: ID # (UC431M1D1B-01) SW B530 | K27: MeWP 80W STLA EVO BCP0044 | L27: ID # (UC431M1D2B-01 SW BC60)
A28: 26 | B28: S210 | C28: Soft Tool | D28: 14 | E28: MeWP200W STLA-F TRIPUMP0045 | F28: ID # (PLUC431M1D0A-01) SW:B1C0 | G28: IC0 | H28: 09.08.2023MeWP 80W STLA-F TP EDM0037 | I28: ID # (UC431M1D1B-01) SW B530 | K28: MeWP 80W STLA EVO BCP0038 | L28: ID # (UC431M1D2B-01 SW BC60)
A29: 27 | B29: S212 | C29: Soft Tool 80MeWP hardware changes on both | D29: 1 | E29: MeWP200W STLA-F TRIPUMP0034 | F29: ID # (PLUC431M1D0A-01) SW: was B1C0, Reflashed to B1C1 Feb2, 2024 | G29: IC0 | H29: 09.08.2023MeWP 80W STLA-F TP EDM0031 | I29: ID # (UC431M1D1B-01) SW B530 | J29: ME1 | K29: MeWP 80W STLA EVO BCP0045 | L29: ID # (UC431M1D2B-01 SW BC60) | M29: MD1 | N29: Assigned to ALT -- TR.CC24.00229
A30: 28 | B30: S212 reworked | C30: Soft Tool 80MeWP hardware changes on both | D30: 1 | E30: was MeWP200W STLA-F TRIPUMP0067 Now replaced with S/N 0038 Apr 22 | F30: ID # (PLUC431M1D0A-01) SW: was B1C0, Reflashed to B1C1 Feb2, 2024 | G30: IC0 | H30: 15.12.2023MeWP 80W STLA-F TP EDM0067 | I30: ID # (UC431M1D1B-01) SW B530 | J30: ME1 | K30: MeWP 80W STLA EVO BCP0077 | L30: ID # (UC431M1D2B-01 SW BC60) | M30: MD1 | N30: Assigned to Speed Derating test -- TR.CC24.00492 | O30: Audit test after derating test TR.CC24.03605 (02/16/24) | P30: 2 life cycle
A31: 29 | B31: S213 | C31: Soft Tool 80MeWP hardware changes on both | D31: 2 | E31: MeWP200W STLA-F TRIPUMP0065 | F31: ID # (PLUC431M1D0A-01) SW: was B1C0, Reflashed to B1C1 Feb2, 2024 | G31: IC0 | H31: 15.12.2023MeWP 80W STLA-F TP EDM0062 | I31: ID # (UC431M1D1B-01) SW B530 | J31: ME1 | K31: MeWP 80W STLA EVO BCP0075 | L31: ID # (UC431M1D2B-01 SW BC60) | M31: MD1 | N31: Audit test TR.CC23.22950 | O31: Assigned to Leg 1 TS & PTCE TR.CC23.22663
A32: 30 | B32: S214 | C32: Soft Tool 80MeWP hardware changes on both | D32: 3 | E32: MeWP200W STLA-F TRIPUMP0066 | F32: ID # (PLUC431M1D0A-01) SW: was B1C0, Reflashed to B1C1 Feb2, 2024 | G32: IC0 | H32: 15.12.2023MeWP 80W STLA-F TP EDM0063 | I32: ID # (UC431M1D1B-01) SW B530 | J32: ME1 | K32: MeWP 80W STLA EVO BCP0076 | L32: ID # (UC431M1D2B-01 SW BC60) | M32: MD1 | N32: Audit test TR.CC23.22950 | O32: Assigned to Leg 1 TS & PTCE TR.CC23.22663
A33: 31 | B33: S215 | C33: Soft Tool 80MeWP hardware changes on both | D33: 4 | E33: MeWP200W STLA-F TRIPUMP0068 | F33: ID # (PLUC431M1D0A-01) SW: was B1C0, Reflashed to B1C1 Feb2, 2024 | G33: IC0 | H33: 15.12.2023MeWP 80W STLA-F TP EDM0068 | I33: ID # (UC431M1D1B-01) SW B530 | J33: ME1 | K33: was MeWP 80W STLA EVO BCP0078; now 0082 Apr17, 2024 | L33: ID # (UC431M1D2B-01 SW BC60) | M33: MD1 | N33: Audit test TR.CC23.22950 | O33: Assigned to Leg 7 Life Test -- TR.CC23.25656
A34: 32 | B34: S216 | C34: Soft Tool 80MeWP hardware changes on both | D34: 1 | E34: MeWP200W STLA-F TRIPUMP0080 | F34: ID # (PLUC431M1D0A-01) SW: was B1C0, Reflashed to B1C1 Feb2, 2024 | G34: IC0 | H34: 15.12.2023MeWP 80W STLA-F TP EDM0071 | I34: ID # (UC431M1D1B-01) SW B530 | J34: ME1 | K34: Was MeWP 80W STLA EVO BCP0070; now 0144 Apr19,2024 | L34: ID # (UC431M1D2B-01 SW BC60) | M34: MD1 | N34: Audit test TR.CC23.22950 | O34: Re-built with new GEN pump 2/07/24 | P34: Re-audit test TR.CC24.02923 | Q34: Assigned to Leg 7 Life Test -- TR.CC23.25656
A35: 33 | B35: S217 | C35: Soft Tool 80MeWP hardware changes on both | D35: 2 | E35: MeWP200W STLA-F TRIPUMP0074 | F35: ID # (PLUC431M1D0A-01) SW: was B1C0, Reflashed to B1C1 Feb2, 2024 | G35: IC0 | H35: 15.12.2023MeWP 80W STLA-F TP EDM0061 | I35: ID # (UC431M1D1B-01) SW B530 | J35: ME1 | K35: MeWP 80W STLA EVO BCP0069 | L35: ID # (UC431M1D2B-01 SW BC60) | M35: MD1 | N35: Audit test TR.CC24.01600 | O35: Re-built with new GEN pump 2/07/24 | P35: Re-audit test TR.CC24.02923
A36: 34 | B36: S218 | C36: Soft Tool 80MeWP hardware changes on both | D36: 3 | E36: MeWP200W STLA-F TRIPUMP0061 | F36: ID # (PLUC431M1D0A-01) SW: was B1C0, Reflashed to B1C1 Feb2, 2024 | G36: IC0 | H36: 15.12.2023MeWP 80W STLA-F TP EDM0065 | I36: ID # (UC431M1D1B-01) SW B530 | J36: ME1 | K36: Was MeWP 80W STLA EVO BCP0064; now 0143 Apr 19, 2024 | L36: ID # (UC431M1D2B-01 SW BC60) | M36: MD1 | N36: Audit test TR.CC24.01600 | O36: Assigned to Leg 7 Life Test -- TR.CC23.25656
A37: 35 | B37: S219 | C37: Soft Tool 80MeWP hardware changes on both | D37: 4 | E37: MeWP200W STLA-F TRIPUMP0081 | F37: ID # (PLUC431M1D0A-01) SW: was B1C0, Reflashed to B1C1 Feb2, 2024 | G37: IC0 | H37: 15.12.2023MeWP 80W STLA-F TP EDM0070 | I37: ID # (UC431M1D1B-01) SW B530 | J37: ME1 | K37: MeWP 80W STLA EVO BCP0060 | L37: ID # (UC431M1D2B-01 SW BC60) | M37: MD1 | N37: Audit test TR.CC24.01600 | O37: Re-built with new GEN pump 2/07/24 | P37: Re-audit test TR.CC24.02923
A38: 36 | B38: S220 | C38: Soft Tool 80MeWP hardware changes on both | D38: 8 | E38: MeWP200W STLA-F TRIPUMP0064 | F38: ID # (PLUC431M1D0A-01) SW: was B1C0, Reflashed to B1C1 Feb2, 2024 | G38: IC0 | H38: 15.12.2023MeWP 80W STLA-F TP EDM0064 | I38: ID # (UC431M1D1B-01) SW B530 | J38: ME1 | K38: MeWP 80W STLA EVO BCP0063 | L38: ID # (UC431M1D2B-01 SW BC60) | M38: MD1 | N38: Audit test TR.CC24.01600 | O38: Re-built with new GEN pump 2/07/24 | P38: Re-audit test TR.CC24.02923
A39: 37 | B39: S221 | C39: Soft Tool 80MeWP hardware changes on both | D39: 10 | E39: MeWP200W STLA-F TRIPUMP0082 | F39: ID # (PLUC431M1D0A-01) SW: was B1C0, Reflashed to B1C1 Feb2, 2024 | G39: IC0 | H39: 15.12.2023MeWP 80W STLA-F TP EDM0078 | I39: ID # (UC431M1D1B-01) SW B530 | J39: ME1 | K39: MeWP 80W STLA EVO BCP0074 | L39: ID # (UC431M1D2B-01 SW BC60) | M39: MD1 | N39: Audit test TR.CC24.01600 | O39: Re-built with new GEN pump 2/07/24 | P39: Re-audit test TR.CC24.02923
A40: 38 | B40: S222 | C40: Soft Tool 80MeWP hardware changes on both | D40: 11 | E40: MeWP200W STLA-F TRIPUMP0071 | F40: ID # (PLUC431M1D0A-01) SW: was B1C0, Reflashed to B1C1 Feb2, 2024 | G40: IC0 | H40: 15.12.2023MeWP 80W STLA-F TP EDM0069 | I40: ID # (UC431M1D1B-01) SW B530 | J40: ME1 | K40: MeWP 80W STLA EVO BCP0061 | L40: ID # (UC431M1D2B-01 SW BC60) | M40: MD1 | N40: Audit test TR.CC24.02109 | O40: Re-built with new GEN pump 2/07/24 | P40: Re-audit test TR.CC24.02923
A41: 39 | B41: S223 | C41: Soft Tool 80MeWP hardware changes on both | D41: 12 | E41: MeWP200W STLA-F TRIPUMP0073 | F41: ID # (PLUC431M1D0A-01) SW: was B1C0, Reflashed to B1C1 Feb2, 2024 | G41: IC0 | H41: 15.12.2023MeWP 80W STLA-F TP EDM0072 | I41: ID # (UC431M1D1B-01) SW B530 | J41: ME1 | K41: MeWP 80W STLA EVO BCP0065 | L41: ID # (UC431M1D2B-01 SW BC60) | M41: MD1 | N41: Audit test TR.CC24.02109 | O41: Re-built with new GEN pump 2/07/24 | P41: Re-audit test TR.CC24.02923
A42: 40 | B42: S224 | C42: Soft Tool 80MeWP hardware changes on both | D42: 13 | E42: MeWP200W STLA-F TRIPUMP0075 | F42: ID # (PLUC431M1D0A-01) SW: was B1C0, Reflashed to B1C1 Feb2, 2024 | G42: IC0 | H42: 15.12.2023MeWP 80W STLA-F TP EDM0074 | I42: ID # (UC431M1D1B-01) SW B530 | J42: ME1 | K42: MeWP 80W STLA EVO BCP0066 | L42: ID # (UC431M1D2B-01 SW BC60) | M42: MD1 | N42: Audit test TR.CC24.02109 | O42: Re-built with new GEN pump 2/07/24 | P42: Re-audit test TR.CC24.02923
A43: 41 | B43: S225 | C43: Soft Tool 80MeWP hardware changes on both | D43: 14 | E43: MeWP200W STLA-F TRIPUMP0076 | F43: ID # (PLUC431M1D0A-01) SW: was B1C0, Reflashed to B1C1 Feb2, 2024 | G43: IC0 | H43: 15.12.2023MeWP 80W STLA-F TP EDM0076 | I43: ID # (UC431M1D1B-01) SW B530 | J43: ME1 | K43: MeWP 80W STLA EVO BCP0079 | L43: ID # (UC431M1D2B-01 SW BC60) | M43: MD1 | N43: Audit test TR.CC24.02109 | O43: Re-built with new GEN pump 2/07/24 | P43: Re-audit test TR.CC24.02923
A44: 42 | B44: S226 | C44: Soft Tool 80MeWP hardware changes on both | D44: 15 | E44: MeWP200W STLA-F TRIPUMP0098 | F44: ID # (PLUC431M1D0A-01) SW:B1C1 | G44: IC0 | H44: 10.01.2024MeWP 80W STLA-F TP EDM0106 | I44: ID # (UC431M1D1B-01) SW B530 | J44: ME1 | K44: MeWP 80W STLA EVO BCP0081 | L44: ID # (UC431M1D2B-01 SW BC60) | M44: MD1 | N44: Audit test TR.CC24.02109 | O44: Assigned to Leg 3 -- TR.CC24.03375
...

Sheet Formula
B3: =Total!A9 -> S260 | C3: =Total!B9 -> 52 | D3: =Total!D9 -> MeWP200W STLA-F TRIPUMP0105 | E3: =Total!$D$8 -> ID # (PLUC431M1D0A-01) SW:B1C1 | F3: =Total!G9 -> 23.01.2024MeWP 80W STLA-F TP EDM0116 | G3: =Total!$G$8 -> ID # (UC431M1D1B-01) SW B530 Aluminum Housing | H3: =Total!J9 -> MeWP 80W STLA EVO BCP0102 | I3: =Total!$J$8 -> ID # (UC431M1D2B-01 SW BC60) Plastic Housing
B4: =Total!A10 -> S261 | C4: =Total!B10 -> 55 | D4: =Total!D10 -> MeWP200W STLA-F TRIPUMP0112 | E4: =Total!$D$8 -> ID # (PLUC431M1D0A-01) SW:B1C1 | F4: =Total!G10 -> 10.01.2024MeWP 80W STLA-F TP EDM0094 | G4: =Total!$G$8 -> ID # (UC431M1D1B-01) SW B530 Aluminum Housing | H4: =Total!J10 -> MeWP 80W STLA EVO BCP0108 | I4: =Total!$J$8 -> ID # (UC431M1D2B-01 SW BC60) Plastic Housing
B5: =Total!A11 -> S247 | C5: =Total!B11 -> 34 | D5: =Total!D11 -> MeWP200W STLA-F TRIPUMP0091 | E5: =Total!$D$8 -> ID # (PLUC431M1D0A-01) SW:B1C1 | F5: =Total!G11 -> 10.01.2024MeWP 80W STLA-F TP EDM0093 | G5: =Total!$G$8 -> ID # (UC431M1D1B-01) SW B530 Aluminum Housing | H5: =Total!J11 -> MeWP 80W STLA EVO BCP0111 | I5: =Total!$J$8 -> ID # (UC431M1D2B-01 SW BC60) Plastic Housing
B6: =Total!A12 -> S248 | C6: =Total!B12 -> 38 | D6: =Total!D12 -> MeWP200W STLA-F TRIPUMP0095 | E6: =Total!$D$8 -> ID # (PLUC431M1D0A-01) SW:B1C1 | F6: =Total!G12 -> 10.01.2024MeWP 80W STLA-F TP EDM0095 | G6: =Total!$G$8 -> ID # (UC431M1D1B-01) SW B530 Aluminum Housing | H6: =Total!J12 -> MeWP 80W STLA EVO BCP0100 | I6: =Total!$J$8 -> ID # (UC431M1D2B-01 SW BC60) Plastic Housing
B7: =Total!A13 -> S249 | C7: =Total!B13 -> 39 | D7: =Total!D13 -> MeWP200W STLA-F TRIPUMP0088 | E7: =Total!$D$8 -> ID # (PLUC431M1D0A-01) SW:B1C1 | F7: =Total!G13 -> 10.01.2024MeWP 80W STLA-F TP EDM0085 | G7: =Total!$G$8 -> ID # (UC431M1D1B-01) SW B530 Aluminum Housing | H7: =Total!J13 -> MeWP 80W STLA EVO BCP0119 | I7: =Total!$J$8 -> ID # (UC431M1D2B-01 SW BC60) Plastic Housing
B8: =Total!A14 -> S250 | C8: =Total!B14 -> 40 | D8: =Total!D14 -> MeWP200W STLA-F TRIPUMP0079 | E8: =Total!$D$8 -> ID # (PLUC431M1D0A-01) SW:B1C1 | F8: =Total!G14 -> 23.01.2024MeWP 80W STLA-F TP EDM0117 | G8: =Total!$G$8 -> ID # (UC431M1D1B-01) SW B530 Aluminum Housing | H8: =Total!J14 -> MeWP 80W STLA EVO BCP0083 | I8: =Total!$J$8 -> ID # (UC431M1D2B-01 SW BC60) Plastic Housing
B9: =Total!A15 -> S251 | C9: =Total!B15 -> 41 | D9: =Total!D15 -> MeWP200W STLA-F TRIPUMP0063 | E9: =Total!$D$8 -> ID # (PLUC431M1D0A-01) SW:B1C1 | F9: =Total!G15 -> 10.01.2024MeWP 80W STLA-F TP EDM0097 | G9: =Total!$G$8 -> ID # (UC431M1D1B-01) SW B530 Aluminum Housing | H9: =Total!J15 -> MeWP 80W STLA EVO BCP0105 | I9: =Total!$J$8 -> ID # (UC431M1D2B-01 SW BC60) Plastic Housing
B10: =Total!A16 -> S252 | C10: =Total!B16 -> 42 | D10: =Total!D16 -> MeWP200W STLA-F TRIPUMP0039 | E10: =Total!$D$8 -> ID # (PLUC431M1D0A-01) SW:B1C1 | F10: =Total!G16 -> 23.01.2024MeWP 80W STLA-F TP EDM0114 | G10: =Total!$G$8 -> ID # (UC431M1D1B-01) SW B530 Aluminum Housing | H10: =Total!J16 -> MeWP 80W STLA EVO BCP0118 | I10: =Total!$J$8 -> ID # (UC431M1D2B-01 SW BC60) Plastic Housing
B11: =Total!A17 -> S253 | C11: =Total!B17 -> 29 | D11: =Total!D17 -> MeWP200W STLA-F TRIPUMP0062 | E11: =Total!$D$8 -> ID # (PLUC431M1D0A-01) SW:B1C1 | F11: =Total!G17 -> 10.01.2024MeWP 80W STLA-F TP EDM0096 | G11: =Total!$G$8 -> ID # (UC431M1D1B-01) SW B530 Aluminum Housing | H11: =Total!J17 -> MeWP 80W STLA EVO BCP0104 | I11: =Total!$J$8 -> ID # (UC431M1D2B-01 SW BC60) Plastic Housing
B12: =Total!A18 -> S254 | C12: =Total!B18 -> 30 | D12: =Total!D18 -> MeWP200W STLA-F TRIPUMP0078 | E12: =Total!$D$8 -> ID # (PLUC431M1D0A-01) SW:B1C1 | F12: =Total!G18 -> 10.01.2024MeWP 80W STLA-F TP EDM0110 | G12: =Total!$G$8 -> ID # (UC431M1D1B-01) SW B530 Aluminum Housing | H12: =Total!J18 -> MeWP 80W STLA EVO BCP0107 | I12: =Total!$J$8 -> ID # (UC431M1D2B-01 SW BC60) Plastic Housing
B13: =Total!A19 -> S255 | C13: =Total!B19 -> 31 | D13: =Total!D19 -> MeWP200W STLA-F TRIPUMP0060 | E13: =Total!$D$8 -> ID # (PLUC431M1D0A-01) SW:B1C1 | F13: =Total!G19 -> 10.01.2024MeWP 80W STLA-F TP EDM0112 | G13: =Total!$G$8 -> ID # (UC431M1D1B-01) SW B530 Aluminum Housing | H13: =Total!J19 -> MeWP 80W STLA EVO BCP0103 | I13: =Total!$J$8 -> ID # (UC431M1D2B-01 SW BC60) Plastic Housing
B14: =Total!A20 -> S256 | C14: =Total!B20 -> 32 | D14: =Total!D20 -> MeWP200W STLA-F TRIPUMP0111 | E14: =Total!$D$8 -> ID # (PLUC431M1D0A-01) SW:B1C1 | F14: =Total!G20 -> 10.01.2024MeWP 80W STLA-F TP EDM0088 | G14: =Total!$G$8 -> ID # (UC431M1D1B-01) SW B530 Aluminum Housing | H14: =Total!J20 -> MeWP 80W STLA EVO BCP0114 | I14: =Total!$J$8 -> ID # (UC431M1D2B-01 SW BC60) Plastic Housing
... B89: =Total!A95 -> S272 | C89: =Total!B95 -> 56 | D89: =Total!D95 -> MeWP200W STLA-F TRIPUMP0138 | E89: =Total!$D$8 -> ID # (PLUC431M1D0A-01) SW:B1C1 | F89: =Total!G95 -> 30.01.2024MeWP 80W STLA-F TP EDM0123 | G89: =Total!$G$8 -> ID # (UC431M1D1B-01) SW B530 Aluminum Housing | H89: =Total!J95 -> MeWP 80W STLA EVO BCP0132 | I89: =Total!$J$8 -> ID # (UC431M1D2B-01 SW BC60) Plastic Housing

Sheet Total
A5: TR # | C5: CC24.03240 | F5: Date: | G5: 45338
A6: Program: | C6: Stellantis Coolant Control Module | F6: Technician: | G6: PN
A7: Assembly ID | B7: Manifold | D7: MeWP200 | G7: MeWP80 (EDM) | J7: MeWP80 (EVO) | M7: 3 Isolators Installed in Correct Direction? | N7: Leak Test at 1.4bar & 192cc Volume (<0.5cc/min) | O7: Label(s) Applied ?
B8: ID # | C8: Gauge Check (Pass/Fail) | D8: ID # (PLUC431M1D0A-01) SW:B1C1 | E8: O-ring installed? | F8: Screws Torque (2.6±0.2Nm @500rpm) | G8: ID # (UC431M1D1B-01) SW B530 Aluminum Housing | H8: O-ring Installed? | I8: Screws Torque (2.6±0.2Nm @500rpm) | J8: ID # (UC431M1D2B-01 SW BC60) Plastic Housing | K8: O-ring Installed? | L8: Screws Torque (2.6±0.2Nm @500rpm)
A9: S260 | B9: 52 | C9: F 0.05 | D9: MeWP200W STLA-F TRIPUMP0105 | E9: Y | F9: 2.58~2.67 | G9: 23.01.2024MeWP 80W STLA-F TP EDM0116 | H9: Y | I9: 2.65~2.78 | J9: MeWP 80W STLA EVO BCP0102 | K9: Y | L9: 2.55~2.63 | M9: Y | N9: 0.407 | O9: Y
A10: S261 | B10: 55 | C10: P | D10: MeWP200W STLA-F TRIPUMP0112 | E10: Y | F10: 2.64~2.72 | G10: 10.01.2024MeWP 80W STLA-F TP EDM0094 | H10: Y | I10: 2.66~2.78 | J10: MeWP 80W STLA EVO BCP0108 | K10: Y | L10: 2.55~2.60 | M10: Y | N10: 0.393 | O10: Y
A11: S247 | B11: 34 | C11: P | D11: MeWP200W STLA-F TRIPUMP0091 | E11: Y | F11: 2.59~2.71 | G11: 10.01.2024MeWP 80W STLA-F TP EDM0093 | H11: Y | I11: 2.71~2.80 | J11: MeWP 80W STLA EVO BCP0111 | K11: Y | L11: 2.55~2.67 | M11: Y | N11: 0.41 | O11: Y
A12: S248 | B12: 38 | C12: F 0.1 | D12: MeWP200W STLA-F TRIPUMP0095 | E12: Y | F12: 2.62~2.69 | G12: 10.01.2024MeWP 80W STLA-F TP EDM0095 | H12: Y | I12: 2.66~2.76 | J12: MeWP 80W STLA EVO BCP0100 | K12: Y | L12: 2.53~2.58 | M12: Y | N12: 0.9~1.1 | O12: Y
A13: S249 | B13: 39 | C13: F 0.05 | D13: MeWP200W STLA-F TRIPUMP0088 | E13: Y | F13: 2.61~2.75 | G13: 10.01.2024MeWP 80W STLA-F TP EDM0085 | H13: Y | I13: 2.63~2.78 | J13: MeWP 80W STLA EVO BCP0119 | K13: Y | L13: 2.56~2.61 | M13: Y | N13: 0.459 | O13: Y
A14: S250 | B14: 40 | C14: F 0.06 | D14: MeWP200W STLA-F TRIPUMP0079 | E14: Y | F14: 2.59~2.73 | G14: 23.01.2024MeWP 80W STLA-F TP EDM0117 | H14: Y | I14: 2.73~2.80 | J14: MeWP 80W STLA EVO BCP0083 | K14: Y | L14: 2.56~2.65 | M14: Y | N14: 0.367 | O14: Y
A15: S251 | B15: 41 | C15: P | D15: MeWP200W STLA-F TRIPUMP0063 | E15: Y | F15: 2.59~2.73 | G15: 10.01.2024MeWP 80W STLA-F TP EDM0097 | H15: Y | I15: 2.71~2.76 | J15: MeWP 80W STLA EVO BCP0105 | K15: Y | L15: 2.61~2.63 | M15: Y | N15: 0.387 | O15: Y
A16: S252 | B16: 42 | C16: F 0.1 | D16: MeWP200W STLA-F TRIPUMP0039 | E16: Y | F16: 2.71~2.77 | G16: 23.01.2024MeWP 80W STLA-F TP EDM0114 | H16: Y | I16: 2.75~2.78 | J16: MeWP 80W STLA EVO BCP0118 | K16: Y | L16: 2.59~2.61 | M16: Y | N16: 0.407 | O16: Y
A17: S253 | B17: 29 | C17: F 0.10 | D17: MeWP200W STLA-F TRIPUMP0062 | E17: Y | F17: 2.62~2.76 | G17: 10.01.2024MeWP 80W STLA-F TP EDM0096 | H17: Y | I17: 2.66~2.71 | J17: MeWP 80W STLA EVO BCP0104 | K17: Y | L17: 2.55~2.69 | M17: Y | N17: 0.367 | O17: Y
A18: S254 | B18: 30 | C18: F 0.17 | D18: MeWP200W STLA-F TRIPUMP0078 | E18: Y | F18: 2.53~2.73 | G18: 10.01.2024MeWP 80W STLA-F TP EDM0110 | H18: Y | I18: 2.67~2.74 | J18: MeWP 80W STLA EVO BCP0107 | K18: Y | L18: 2.55~2.63 | M18: Y | N18: 0.413 | O18: Y
A19: S255 | B19: 31 | C19: F 0.14 | D19: MeWP200W STLA-F TRIPUMP0060 | E19: Y | F19: 2.63~2.70 | G19: 10.01.2024MeWP 80W STLA-F TP EDM0112 | H19: Y | I19: 2.70~2.80 | J19: MeWP 80W STLA EVO BCP0103 | K19: Y | L19: 2.56~2.62 | M19: Y | N19: 0.436 | O19: Y
A20: S256 | B20: 32 | C20: F 0.09 | D20: MeWP200W STLA-F TRIPUMP0111 | E20: Y | F20: 2.61~2.69 | G20: 10.01.2024MeWP 80W STLA-F TP EDM0088 | H20: Y | I20: 2.66~2.79 | J20: MeWP 80W STLA EVO BCP0114 | K20: Y | L20: 2.59~2.63 | M20: Y | N20: 0.381 | O20: Y
A21: S257 | B21: 33 | C21: F 0.02 | D21: MeWP200W STLA-F TRIPUMP0114 | E21: Y | F21: 2.63~2.76 | G21: 10.01.2024MeWP 80W STLA-F TP EDM0111 | H21: Y | I21: 2.67~2.75 | J21: MeWP 80W STLA EVO BCP0109 | K21: Y | L21: 2.56~2.59 | M21: Y | N21: 0.381 | O21: Y
A22: S258 | B22: 49 | C22: F 0.1 | D22: MeWP200W STLA-F TRIPUMP0090 | E22: Y | F22: 2.56~2.76 | G22: 10.01.2024MeWP 80W STLA-F TP EDM0089 | H22: Y | I22: 2.63~2.75 | J22: MeWP 80W STLA EVO BCP0095 | K22: Y | L22: 2.56~2.60 | M22: Y | N22: 0.381 | O22: Y
A23: S227 | B23: 16 | C23: F 0.02 | D23: MeWP200W STLA-F TRIPUMP0123 | E23: Y | F23: 2.60~2.65 | G23: 23.01.2024MeWP 80W STLA-F TP EDM0120 | H23: Y | I23: 2.68~2.77 | J23: MeWP 80W STLA EVO BCP0101 | K23: Y | L23: 2.54~2.62 | M23: Y | N23: 0.396 | O23: Y
A24: S228 | B24: 17 | C24: P | D24: MeWP200W STLA-F TRIPUMP0093 | E24: Y | F24: 2.62~2.68 | G24: 10.01.2024MeWP 80W STLA-F TP EDM0107 | H24: Y | I24: 2.64~2.77 | J24: MeWP 80W STLA EVO BCP0098 | K24: Y | L24: 2.55~2.64 | M24: Y | N24: 0.417 | O24: Y
... A30: S234 | B30: 23 | C30: P | D30: MeWP200W STLA-F TRIPUMP0085 | E30: Y | F30: 2.57~2.68 | G30: 10.01.2024MeWP 80W STLA-F TP EDM0083 | H30: Y | I30: 2.74~2.80 | J30: MeWP 80W STLA EVO BCP0096 | K30: Y | L30: 2.54~2.62 | M30: Y | N30: 0.351 | O30: Y
A31: S235 | B31: 24 | C31: F 0.02 | D31: MeWP200W STLA-F TRIPUMP0100 | E31: Y | F31: 2.63~2.69 | G31: 10.01.2024MeWP 80W STLA-F TP EDM0109 | H31: Y | I31: 2.60~2.68 | J31: MeWP 80W STLA EVO BCP0093 | K31: Y | L31: 2.56~2.58 | M31: Y | N31: Manifold Leaking | O31: Y
A32: S236 | B32: 25 | C32: F 0.06 | D32: MeWP200W STLA-F TRIPUMP0122 | E32: Y | F32: 2.62~2.67 | G32: 15.12.2023MeWP 80W STLA-F TP EDM0082 | H32: Y | I32: 2.66~2.75 | J32: MeWP 80W STLA EVO BCP0088 | K32: Y | L32: 2.51~2.60 | M32: Y | N32: 0.456 | O32: Y
A33: S237 | B33: 26 | C33: F 0.11 | D33: MeWP200W STLA-F TRIPUMP0109 | E33: Y | F33: 2.63~2.72 | G33: 10.01.2024MeWP 80W STLA-F TP EDM0092 | H33: Y | I33: 2.76~2.79 | J33: MeWP 80W STLA EVO BCP0099 | K33: Y | L33: 2.57~2.64 | M33: Y | N33: 0.456 | O33: Y
A34: S238 | B34: 27 | C34: F 0.1 | D34: MeWP200W STLA-F TRIPUMP0102 | E34: Y | F34: 2.62~2.76 | G34: 10.01.2024MeWP 80W STLA-F TP EDM0102 | H34: Y | I34: 2.72~2.77 | J34: MeWP 80W STLA EVO BCP0084 | K34: Y | L34: 2.57~2.63 | M34: Y | N34: 0.414 | O34: Y
A35: S239 | B35: 28 | C35: F 0.08 | D35: MeWP200W STLA-F TRIPUMP0092 | E35: Y | F35: 2.62~2.74 | G35: 23.01.2024MeWP 80W STLA-F TP EDM0118 | H35: Y | I35: 2.71~2.76 | J35: MeWP 80W STLA EVO BCP0086 | K35: Y | L35: 2.57~2.65 | M35: Y | N35: 0.435 | O35: Y
A36: S240 | B36: 5 | C36: F 0.06 | D36: MeWP200W STLA-F TRIPUMP0087 | E36: Y | F36: 2.67~2.80 | G36: 10.01.2024MeWP 80W STLA-F TP EDM0087 | H36: Y | I36: 2.72~2.80 | J36: MeWP 80W STLA EVO BCP0094 | K36: Y | L36: 2.60~2.65 | M36: Y | N36: 0.433 | O36: Y
A37: S241 | B37: 6 | C37: F 0.08 | D37: MeWP200W STLA-F TRIPUMP0108 | E37: Y | F37: 2.64~2.70 | G37: 10.01.2024MeWP 80W STLA-F TP EDM0100 | H37: Y | I37: 2.73~2.79 | J37: MeWP 80W STLA EVO BCP0112 | K37: Y | L37: 2.50~2.57 | M37: Y | N37: 0.433 | O37: Y
A38: S242 | B38: 7 | C38: F 0.13 | D38: MeWP200W STLA-F TRIPUMP0107 | E38: Y | F38: 2.66~2.74 | G38: 10.01.2024MeWP 80W STLA-F TP EDM0099 | H38: Y | I38: 2.69~2.79 | J38: MeWP 80W STLA EVO BCP0097 | K38: Y | L38: 2.61~2.63 | M38: Y | N38: 0.451 | O38: Y
A39: S243 | B39: 9 | C39: F 0.08 | D39: MeWP200W STLA-F TRIPUMP0115 | E39: Y | F39: 2.58~2.80 | G39: 10.01.2024MeWP 80W STLA-F TP EDM0086 | H39: Y | I39: 2.70~2.80 | J39: MeWP 80W STLA EVO BCP0085 | K39: Y | L39: 2.60~2.62 | M39: Y | N39: 0.441 | O39: Y
A40: S244 | B40: 35 | C40: F 0.04 | D40: MeWP200W STLA-F TRIPUMP0121 | E40: Y | F40: 2.62~2.72 | G40: 15.12.2023MeWP 80W STLA-F TP EDM0081 | H40: Y | I40: 2.66~2.80 | J40: MeWP 80W STLA EVO BCP0091 | K40: Y | L40: 2.59~2.66 | M40: Y | N40: 0.441 | O40: Y
A41: S245 | B41: 36 | C41: F 0.07 | D41: MeWP200W STLA-F TRIPUMP0116 | E41: Y | F41: 2.58~2.66 | G41: 10.01.2024MeWP 80W STLA-F TP EDM0101 | H41: Y | I41: 2.70~2.77 | J41: MeWP 80W STLA EVO BCP0087 | K41: Y | L41: 2.55~2.62 | M41: Y | N41: Manifold Leaking | O41: Y
A42: S246 | B42: 37 | C42: F 0.03 | D42: MeWP200W STLA-F TRIPUMP0104 | E42: Y | F42: 2.57~2.76 | G42: 10.01.2024MeWP 80W STLA-F TP EDM0104 | H42: Y | I42: 2.72~2.78 | J42: MeWP 80W STLA EVO BCP0089 | K42: Y | L42: 2.57~2.62 | M42: Y | N42: 0.399 | O42: Y
A43: S222 | B43: 11 | C43: FAILED MAX 0.114MM | D43: MeWP200W STLA-F TRIPUMP0071 | E43: Y | F43: 2.55-2.72 | G43: 15.12.2023MeWP 80W STLA-F TP EDM0069 | H43: Y | I43: 2.62-2.71 | J43: MeWP 80W STLA EVO BCP0061 | K43: Y | L43: 2.54-2.58 | M43: Y | N43: 0.412 | O43: Y
A44: S223 | B44: 12 | C44: FAILED MAX 0.124MM | D44: MeWP200W STLA-F TRIPUMP0073 | E44: Y | F44: 2.56-2.70 | G44: 15.12.2023MeWP 80W STLA-F TP EDM0072 | H44: Y | I44: 2.63-2.73 | J44: MeWP 80W STLA EVO BCP0065 | K44: Y | L44: 2.56-2.62 | M44: Y | N44: 0.359 | O44: Y
A45: S224 | B45: 13 | C45: FAILED MAX 0.147MM | D45: MeWP200W STLA-F TRIPUMP0075 | E45: Y | F45: 2.55-2.75 | G45: 15.12.2023MeWP 80W STLA-F TP EDM0074 | H45: Y | I45: 2.64-2.80 | J45: MeWP 80W STLA EVO BCP0066 | K45: Y | L45: 2.64-2.80 | M45: Y | N45: 0.304 | O45: Y
A46: S225 | B46: 14 | C46: FAILED MAX 0.097MM | D46: MeWP200W STLA-F TRIPUMP0076 | E46: Y | F46: 2.56-2.69 | G46: 15.12.2023MeWP 80W STLA-F TP EDM0076 | H46: Y | I46: 2.59-2.71 | J46: MeWP 80W STLA EVO BCP0079 | K46: Y | L46: 2.59-2.71 | M46: Y | N46: 0.304 | O46: Y
A47: S226 | B47: 15 | C47: FAILED 0.030MM | D47: MeWP200W STLA-F TRIPUMP0098 | E47: Y | F47: 2.55-2.63 | G47: 10.01.2024MeWP 80W STLA-F TP EDM0106 | H47: Y | I47: 2.66-2.72 | J47: MeWP 80W STLA EVO BCP0081 | K47: Y | L47: 2.50-2.66 | M47: Y | N47: 0.454 | O47: Y
A48: S217 | B48: 2 | C48: F (0.11mm Max) | D48: MeWP200W STLA-F TRIPUMP0074 | E48: Y | F48: 2.57~2.69 | G48: 15.12.2023MeWP 80W STLA-F TP EDM0061 | H48: Y | I48: 2.72~2.74 | J48: MeWP 80W STLA EVO BCP0069 | K48: Y | L48: 2.53~2.63 | M48: Y | N48: 0.34 | O48: Y
A49: S218 | B49: 3 | C49: F (0.108mm Max) | D49: MeWP200W STLA-F TRIPUMP0061 | E49: Y | F49: 2.62~2.71 | G49: 15.12.2023MeWP 80W STLA-F TP EDM0065 | H49: Y | I49: 2.64~2.74 | J49: MeWP 80W STLA EVO BCP0064 | K49: Y | L49: 2.59~2.71 | M49: Y | N49: 0.315 | O49: Y
...

Sheet 19
A5: TR # | C5: CC24.04777 | F5: Date: | G5: 45369
A6: Program: | C6: Stellantis Coolant Control Module | F6: Technician: | G6: PN
A7: Assembly ID | B7: Manifold | D7: MeWP200 | G7: MeWP80 (EDM) | J7: MeWP80 (EVO) | M7: 3 Isolators Installed in Correct Direction? | N7: Leak Test at 1.4bar & 192cc Volume (<0.5cc/min) | O7: Label(s) Applied ?
B8: ID # | C8: Gauge Check (Pass/Fail) | D8: ID # (PLUC431M1D0A-01) SW:B1C1 | E8: O-ring installed? | F8: Screws Torque (2.6±0.2Nm @500rpm) | G8: ID # (UC431M1D1B-01) SW B530 Aluminum Housing | H8: O-ring Installed? | I8: Screws Torque (2.6±0.2Nm @500rpm) | J8: ID # (UC431M1D2B-01 SW BC60) Plastic Housing | K8: O-ring Installed? | L8: Screws Torque (2.6±0.2Nm @500rpm)
A9: S262 | B9: 43 | C9: F 0.02 | D9: MeWP200W STLA-F TRIPUMP0135 | E9: Y | F9: 2.56~2.74 | G9: 30.01.2024MeWP 80W STLA-F TP EDM0122 | H9: Y | I9: 2.63~2.72 | J9: MeWP 80W STLA EVO BCP0130 | K9: Y | L9: 2.56~2.58 | M9: Y | N9: 0.289 | O9: Y
A10: S263 | B10: 44 | C10: F 0.02 | D10: MeWP200W STLA-F TRIPUMP0140 | E10: Y | F10: 2.64~2.74 | G10: 30.01.2024MeWP 80W STLA-F TP EDM0125 | H10: Y | I10: 2.62~2.80 | J10: MeWP 80W STLA EVO BCP0125 | K10: Y | L10: 2.54~2.58 | M10: Y | N10: 0.247 | O10: Y
A11: S264 | B11: 45 | C11: F 0.05 | D11: MeWP200W STLA-F TRIPUMP0130 | E11: Y | F11: 2.57~2.71 | G11: 30.01.2024MeWP 80W STLA-F TP EDM0130 | H11: Y | I11: 2.63~2.77 | J11: MeWP 80W STLA EVO BCP0120 | K11: Y | L11: 2.56~2.64 | M11: Y | N11: 0.269 | O11: Y
A12: S265 | B12: 46 | C12: F 0.04 | D12: MeWP200W STLA-F TRIPUMP0129 | E12: Y | F12: 2.59~2.71 | G12: 30.01.2024MeWP 80W STLA-F TP EDM0129 | H12: Y | I12: 2.66~2.71 | J12: MeWP 80W STLA EVO BCP0126 | K12: Y | L12: 2.58~2.63 | M12: Y | N12: 0.305 | O12: Y
A13: S266 | B13: 47 | C13: F 0.03 | D13: MeWP200W STLA-F TRIPUMP0134 | E13: Y | F13: 2.60~2.72 | G13: 30.01.2024MeWP 80W STLA-F TP EDM0124 | H13: Y | I13: 2.60~2.76 | J13: MeWP 80W STLA EVO BCP0131 | K13: Y | L13: 2.59~2.60 | M13: Y | N13: 0.316 | O13: Y
A14: S267 | B14: 48 | C14: P | D14: MeWP200W STLA-F TRIPUMP0139 | E14: Y | F14: 2.58~2.73 | G14: 30.01.2024MeWP 80W STLA-F TP EDM0134 | H14: Y | I14: 2.62~2.79 | J14: MeWP 80W STLA EVO BCP0121 | K14: Y | L14: 2.49~2.62 | M14: Y | N14: 0.316 | O14: Y
A15: S268 | B15: 50 | C15: F 0.03 | D15: MeWP200W STLA-F TRIPUMP0128 | E15: Y | F15: 2.55~2.63 | G15: 30.01.2024MeWP 80W STLA-F TP EDM0133 | H15: Y | I15: 2.62~2.71 | J15: MeWP 80W STLA EVO BCP0122 | K15: Y | L15: 2.56~2.64 | M15: Y | N15: 0.398 | O15: Y
A16: S269 | B16: 51 | C16: P | D16: MeWP200W STLA-F TRIPUMP0133 | E16: Y | F16: 2.62~2.68 | G16: 30.01.2024MeWP 80W STLA-F TP EDM0128 | H16: Y | I16: 2.69~2.77 | J16: MeWP 80W STLA EVO BCP0127 | K16: Y | L16: 2.55~2.58 | M16: Y | N16: 0.315 | O16: Y
A17: S270 | B17: 53 | C17: P | D17: MeWP200W STLA-F TRIPUMP0127 | E17: Y | F17: 2.56~2.80 | G17: 30.01.2024MeWP 80W STLA-F TP EDM0132 | H17: Y | I17: 2.59~2.74 | J17: MeWP 80W STLA EVO BCP0134 | K17: Y | L17: 2.54~2.64 | M17: Y | N17: 0.327 | O17: Y
A18: S271 | B18: 54 | C18: P | D18: MeWP200W STLA-F TRIPUMP0132 | E18: Y | F18: 2.60~2.68 | G18: 30.01.2024MeWP 80W STLA-F TP EDM0127 | H18: Y | I18: 2.67~2.80 | J18: MeWP 80W STLA EVO BCP0128 | K18: Y | L18: 2.52~2.65 | M18: Y | N18: 0.327 | O18: Y
A19: S272 | B19: 56 | C19: P | D19: MeWP200W STLA-F TRIPUMP0138 | E19: Y | F19: 2.61~2.72 | G19: 30.01.2024MeWP 80W STLA-F TP EDM0123 | H19: Y | I19: 2.66~2.75 | J19: MeWP 80W STLA EVO BCP0132 | K19: Y | L19: 2.55~2.62 | M19: Y | N19: 0.339 | O19: Y

Sheet 18
A2: Module ID | B2: BMW Pump Assembly | D2: Lucid Pump Assembly | F2: Lucid Pump Assembly | H2: 3 Isolators Installed in Correct Direction? | I2: Comments
B3: O-Ring installed with P80? | C3: Screws Torque (2.2±0.2Nm) | D3: O-Ring installed with P80? | E3: Screws Torque (2.2±0.2Nm) | F3: O-Ring installed with P80? | G3: Screws Torque (2.2±0.2Nm)
A4: S001 | B4: Y | C4: 2.2 | D4: Y | E4: 2.2 | F4: Y | G4: 2.2 | H4: Y | I4: BMW pump body was filed due to interference

Sheet 17
A2: Module ID | B2: BMW Pump Assembly | D2: Lucid Pump Assembly | F2: Lucid Pump Assembly | H2: 3 Isolators Installed in Correct Direction? | I2: Comments
B3: O-Ring installed with P80? | C3: Screws Torque (2.2±0.2Nm) | D3: O-Ring installed with P80? | E3: Screws Torque (2.2±0.2Nm) | F3: O-Ring installed with P80? | G3: Screws Torque (2.2±0.2Nm)
A4: S002 | B4: Y | C4: 2.2 | D4: Y | E4: 2.2 | F4: Y | G4: 2.2 | H4: Y | I4: Pumps are from RP#1

Sheet 16
A2: Module ID | B2: Manifold Material | C2: BMW Pump Assembly | G2: Lucid Pump 1 Assembly | L2: Lucid Pump 1 Assembly | Q2: 3 Isolators Installed in Correct Direction? | R2: Comments
C3: Impeller Axial Clearance (0.4) | D3: Thrust Washer Adjustment | E3: O-Ring installed with P80? | F3: Screws Torque (2.2±0.2Nm) | G3: ID # | H3: Thrust Washer Installation Height (17.38±0.1) | I3: Thrust Washer Installation Force (kN) | J3: O-Ring installed with P80? | K3: Screws Torque (2.2±0.2Nm) | L3: ID # | M3: Thrust Washer Installation Height (17.38±0.1) | N3: Thrust Washer Installation Force (kN) | O3: O-Ring installed with P80? | P3: Screws Torque (2.2±0.2Nm)
A4: S005 | B4: PA 12 40% Glass Filled | C4: NA | D4: NA | E4: Y (New) | F4: 2 ~ 2.5 | G4: 0016 | H4: NA | I4: NA | J4: Y (Old) | K4: 2 ~ 2.5 | L4: 0026 | M4: NA | N4: NA | O4: Y (Old) | P4: 2 ~ 2.5 | Q4: Y | R4: 2 Lucid Pumps are from RP#1
A5: S006 | B5: PA 12 40% Glass Filled | C5: 0.37mm | D5: 1.5kN | E5: Y (New) | F5: 2 ~ 2.5 | G5: 7286 | H5: 17.33 | I5: 0.28 | J5: Y (New) | K5: 2 ~ 2.5 | L5: 4232 | M5: 17.4 | N5: 0.28 | O5: Y (New) | P5: 2 ~ 2.5 | Q5: Y | R5: Re-built with Thrust Washers to Lucid Pumps
K12: ~ | P12: ~

Sheet 15
A2: Module ID | B2: Manifold Material | C2: BMW Pump Assembly | G2: Lucid Pump 1 Assembly | L2: Lucid Pump 1 Assembly | Q2: 3 Isolators Installed in Correct Direction? | R2: Comments
C3: Impeller Axial Clearance (0.4mm) | D3: Thrust Washer Adjustment Force (kN) | E3: O-Ring installed with P80? | F3: Screws Torque (2.2±0.2Nm) | G3: ID # | H3: Thrust Washer Installation Height (17.38±0.1) | I3: Thrust Washer Installation Force (kN) | J3: O-Ring installed with P80? | K3: Screws Torque (2.2±0.2Nm) | L3: ID # | M3: Thrust Washer Installation Height (17.38±0.1) | N3: Thrust Washer Installation Force (kN) | O3: O-Ring installed with P80? | P3: Screws Torque (2.2±0.2Nm)
A4: S006 | B4: PA 12 40% Glass Filled | C4: 0.37 | D4: 1.5 | E4: Y (New) | F4: 2 ~ 2.5 | G4: 7286 | H4: 17.33 | I4: 0.28 | J4: Y (New) | K4: 2 ~ 2.5 | L4: 4232 | M4: 17.4 | N4: 0.28 | O4: Y (New) | P4: 2 ~ 2.5 | Q4: Y | R4: Re-built with Thrust Washers to Lucid Pump Shafts

Sheet 14
A2: Manifold ID (Material) | B2: BMW Pump Assembly with Thrust Washer Position Adjustment | G2: Lucid Pump 1 Assembly (EDM) | L2: Lucid Pump 2 Assembly (BCP) | Q2: 3 Isolators Installed in Correct Direction? | R2: Comments
B3: Impeller into Rotor (38.95 ±0.2mm) | C3: Thrust Washer into Shaft (18.17 ±0.1mm) | D3: Impeller Axial Clearance (0.4mm ±0.25) | E3: O-Ring installed with P80? | F3: Screws Torque (2.2±0.2Nm) | G3: ID # | H3: Thrust Washer Installation Height (17.38±0.1) | I3: Thrust Washer Installation Force (kN) | J3: O-Ring installed with P80? | K3: Screws Torque (2.2±0.2Nm) | L3: ID # | M3: Thrust Washer Installation Height (17.38±0.1) | N3: Thrust Washer Installation Force (kN) | O3: O-Ring installed with P80? | P3: Screws Torque (2.2±0.2Nm)
A4: S003 | B4: 38.98 (8.2kN) | C4: 18.20 (0.3kN) | D4: 0.25 | E4: Y | F4: 2.4 | G4: 4230 | H4: 17.45 | I4: 0.39 | J4: Y | K4: 2.4 | L4: 7269 | M4: 17.44 | N4: 0.36 | O4: Y | P4: 2.4 | Q4: Y | R4: Screws from Toolcrib
A5: S004 | B5: 38.99 (8.3kN) | C5: 18.07 (0.3kN) | D5: 0.48 | E5: Y | F5: 2.4 | G5: 4241 | H5: 17.39 | I5: 0.33 | J5: Y | K5: 2.4 | L5: 4242 | M5: 17.44 | N5: 0.38 | O5: Y | P5: 2.4 | Q5: Y | R5: Screws from Toolcrib

Sheet 13
A3: TR # | B3: CC23.13734 | G3: Date: | I3: 45101 | T3: CC23.13734 | Y3: Date: | AA3: 45101
A4: Program: | B4: Stellantis Coolant Control Module | G4: Technician: | I4: PN | T4: Stellantis Coolant Control Module | Y4: Technician: | AA4: PN
A5: Manifold ID | B5: MeWP200 | K5: MeWP80 (EDM) | T5: MeWP80 (BCP) | AC5: 3 Isolators Installed in Correct Direction? | AD5: Leak Test at 1.4bar & 192cc Volume (<0.5cc/min) | AE5: Label Applied ?
B6: ID # (UC431M1D0A-01) | C6: Dist. 1 | D6: Dist. 3 (18.17 ±0.1) | E6: Dist.4 (min) | F6: Dist.4 (max) | G6: Dist. 2 (0.4 ±0.25) | H6: Dist.1+ 15.36-Dist4(max) (1.05±0.5) | I6: O-Ring with P80? | J6: Screws Torque (2.2±0.2Nm) | K6: ID # (UC431M1D1B SW B530) | L6: Dist. 1 | M6: Dist. 3 (17.38 ±0.1) Ref. | N6: Dist.4 (min) | O6: Dist.4 (max) | P6: Dist. 2 (0.4 ±0.25) | Q6: Dist.1+ 15.371-Dist4(max) (0.99±0.5) | R6: O-Ring with P80? | S6: Screws Torque (2.2±0.2Nm) | T6: ID # (UC431M1D2B-01 SW XXXX) | U6: Dist. 1 | V6: Dist. 3 (17.38±0.1) (Referance) | W6: Dist.4 (min) | X6: Dist.4 (max) | Y6: Dist. 2 (0.4±0.25) | Z6: Dist.1 +15.371 -Dist.4(max) (0.99±0.5) | AA6: O-Ring with P80? | AB6: Screws Torque (2.2±0.2Nm)
A7: S106 | B7: MeWP200W STLA-F TRIPUMP0005 | C7: 15.91 | D7: 18.09 | E7: 29.86 | F7: 30.18 | G7: 0.32 | H7: 1.09 | I7: Y | J7: 2.4x4 | K7: 09.06.2023MeWP 80W STLA-F TP EDM 0004 | L7: 11.82 | M7: 17.55 | N7: 25.91 | O7: 26.33 | P7: 0.42 | Q7: 0.86 | R7: Y | S7: 2.4x3 | T7: MeWP 80W STLA EVO BCP0007 | U7: 11.79 | V7: 17.61 | W7: 25.99 | X7: 26.4 | Y7: 0.41 | Z7: 0.76 | AA7: Y | AB7: 2.4x3 | AC7: Y | AD7: 0.19 | AE7: Y
A8: S107 | B8: MeWP200W STLA-F TRIPUMP0012 | C8: 15.79 | D8: 17.87 | E8: 29.8 | F8: 29.95 | G8: 0.15 | H8: 1.23 | I8: Y | J8: 2.4x4 | K8: 09.06.2023MeWP 80W STLA-F TP EDM 0013 | L8: 11.74 | M8: 17.54 | N8: 25.93 | O8: 26.37 | P8: 0.44 | Q8: 0.74 | R8: Y | S8: 2.4x3 | T8: MeWP 80W STLA EVO BCP0008 | U8: 11.72 | V8: 17.62 | W8: 26.14 | X8: 26.49 | Y8: 0.35 | Z8: 0.6 | AA8: Y | AB8: 2.4x3 | AC8: Y | AD8: 0.3 | AE8: Y
A9: S108 | B9: MeWP200W STLA-F TRIPUMP0008 | C9: 15.75 | D9: 18.04 | E9: 29.82 | F9: 30.13 | G9: 0.31 | H9: 0.98 | I9: Y | J9: 2.4x4 | K9: 09.06.2023MeWP 80W STLA-F TP EDM 0007 | L9: 11.73 | M9: 17.5 | N9: 25.83 | O9: 26.32 | P9: 0.49 | Q9: 0.78 | R9: Y | S9: 2.4x3 | T9: MeWP 80W STLA EVO BCP0013 | U9: 11.72 | V9: 17.58 | W9: 26.09 | X9: 26.43 | Y9: 0.34 | Z9: 0.66 | AA9: Y | AB9: 2.4x3 | AC9: Y | AD9: 0.25 | AE9: Y
A10: S109 | B10: MeWP200W STLA-F TRIPUMP0007 | C10: 15.79 | D10: 18.01 | E10: 29.8 | F10: 30.1 | G10: 0.3 | H10: 1.05 | I10: Y | J10: 2.4x4 | K10: 09.06.2023MeWP 80W STLA-F TP EDM 0008 | L10: 11.75 | M10: 17.54 | N10: 25.87 | O10: 26.28 | P10: 0.41 | Q10: 0.84 | R10: Y | S10: 2.4x3 | T10: MeWP 80W STLA EVO BCP0006 | U10: 11.67 | V10: 17.63 | W10: 26.2 | X10: 26.55 | Y10: 0.35 | Z10: 0.49 | AA10: Y | AB10: 2.4x3 | AC10: Y | AD10: 0.27 | AE10: Y
A11: S110 | B11: MeWP200W STLA-F TRIPUMP0011 | C11: 15.84 | D11: 18.1 | E11: 29.82 | F11: 30.17 | G11: 0.35 | H11: 1.03 | I11: Y | J11: 2.4x4 | K11: 09.06.2023MeWP 80W STLA-F TP EDM 0015 | L11: 11.75 | M11: 17.53 | N11: 25.9 | O11: 26.31 | P11: 0.41 | Q11: 0.81 | R11: Y | S11: 2.4x3 | T11: MeWP 80W STLA EVO BCP0014 | U11: 11.76 | V11: 17.62 | W11: 26.1 | X11: 26.52 | Y11: 0.42 | Z11: 0.61 | AA11: Y | AB11: 2.4x3 | AC11: Y | AD11: 0.44 | AE11: Y
A12: S111 | B12: MeWP200W STLA-F TRIPUMP0014 | C12: 15.9 | D12: 18.22 | E12: 29.81 | F12: 30.32 | G12: 0.51 | H12: 0.94 | I12: Y | J12: 2.4x4 | K12: 09.06.2023MeWP 80W STLA-F TP EDM 0009 | L12: 11.8 | M12: 17.54 | N12: 25.82 | O12: 26.29 | P12: 0.47 | Q12: 0.88 | R12: Y | S12: 2.4x3 | T12: MeWP 80W STLA EVO BCP0010 | U12: 11.77 | V12: 17.5 | W12: 26 | X12: 26.35 | Y12: 0.35 | Z12: 0.79 | AA12: Y | AB12: 2.4x3 | AC12: Y | AD12: 0.42 | AE12: Y
A13: S112 | B13: MeWP200W STLA-F TRIPUMP0013 | C13: 15.81 | D13: 18.04 | E13: 29.88 | F13: 30.2 | G13: 0.32 | H13: 0.97 | I13: Y | J13: 2.4x4 | K13: 09.06.2023MeWP 80W STLA-F TP EDM 0011 | L13: 11.76 | M13: 17.53 | N13: 25.89 | O13: 26.34 | P13: 0.45 | Q13: 0.79 | R13: Y | S13: 2.4x3 | T13: MeWP 80W STLA EVO BCP0015 | U13: 11.75 | V13: 17.55 | W13: 26.06 | X13: 26.41 | Y13: 0.35 | Z13: 0.71 | AA13: Y | AB13: 2.4x3 | AC13: Y | AD13: 0.38 | AE13: Y

Sheet 12
A3: TR #: | B3: CC23.16872 | G3: Date: | H3: 45131 | T3: CC23.16872 | Y3: Date: | Z3: JULY 24, 2023
A4: Program: | B4: Stellantis Coolant Control Module | G4: Technician: | I4: PN | T4: Stellantis Coolant Control Module | Y4: Technician: | AA4: PN
A5: Manifold ID | B5: MeWP200 | K5: MeWP80 (EDM) | T5: MeWP80 (BCP) | AC5: 3 Isolators Installed in Correct Direction? | AD5: Leak Test at 1.4bar & 192cc Volume (<0.5cc/min) | AE5: Label Applied ?
B6: ID # | C6: Dist. 1 | D6: Dist. 3 (18.17 ±0.1) | E6: Dist.4 (min) | F6: Dist.4 (max) | G6: Dist. 2 (0.4 ±0.25) | H6: Dist.1+ 15.36-Dist4(max) (1.05±0.5) | I6: O-Ring with P80? | J6: Screws Torque (2.2±0.2Nm) | K6: ID # | L6: Dist. 1 | M6: Dist. 3 (17.38 ±0.1) Ref. | N6: Dist.4 (min) | O6: Dist.4 (max) | P6: Dist. 2 (0.4 ±0.25) | Q6: Dist.1+ 15.371-Dist4(max) (0.99±0.5) | R6: O-Ring with P80? | S6: Screws Torque (2.2±0.2Nm) | T6: ID # | U6: Dist. 1 | V6: Dist. 3 (17.38±0.1) (Referance) | W6: Dist.4 (min) | X6: Dist.4 (max) | Y6: Dist. 2 (0.4±0.25) | Z6: Dist.1 +15.371 -Dist.4(max) (0.99±0.5) | AA6: O-Ring with P80? | AB6: Screws Torque (2.2±0.2Nm)
A7: S113 | B7: MeWP200W STLA-F TRIPUMP0028 | C7: 15.88 | D7: 18.07 | E7: 29.86 | F7: 30.19 | G7: 0.33 | H7: 1.05 | I7: Y | J7: 2.4X4 | K7: 21.06.2023MeWP 80W STLA-F TP EDM 0027 | L7: 11.77 | M7: 17.42 | N7: 25.81 | O7: 26.25 | P7: 0.44 | Q7: 0.89 | R7: Y | S7: 2.4X3 | T7: MeWP 80W STLA EVO BCP0018 | U7: 11.72 | V7: 17.72 | W7: 26.28 | X7: 26.67 | Y7: 0.39 | Z7: 0.42 | AA7: Y | AB7: 2.4X3 | AC7: Y | AD7: 0.452 | AE7: Y
A8: S114 | B8: MeWP200W STLA-F TRIPUMP0031 | C8: 15.98 | D8: 18.07 | E8: 29.74 | F8: 30.04 | G8: 0.3 | H8: 1.3 | I8: Y | J8: 2.4X4 | K8: 21.06.2023MeWP 80W STLA-F TP EDM 0023 | L8: 11.8 | M8: 17.42 | N8: 25.91 | O8: 26.33 | P8: 0.42 | Q8: 0.84 | R8: Y | S8: 2.4X3 | T8: MeWP 80W STLA EVO BCP0019 | U8: 11.81 | V8: 17.52 | W8: 26 | X8: 26.45 | Y8: 0.45 | Z8: 0.73 | AA8: Y | AB8: 2.4X3 | AC8: Y | AD8: 0.488 | AE8: Y
A9: S115 | B9: MeWP200W STLA-F TRIPUMP0029 | C9: 15.93 | D9: 18.09 | E9: 29.77 | F9: 30.09 | G9: 0.32 | H9: 1.2 | I9: Y | J9: 2.4X4 | K9: 21.06.2023MeWP 80W STLA-F TP EDM 0026 | L9: 11.77 | M9: 17.4 | N9: 25.83 | O9: 26.28 | P9: 0.45 | Q9: 0.86 | R9: Y | S9: 2.4X3 | T9: MeWP 80W STLA EVO BCP0024 | U9: 11.76 | V9: 17.53 | W9: 26.04 | X9: 26.49 | Y9: 0.45 | Z9: 0.64 | AA9: Y | AB9: 2.4X3 | AC9: Y | AD9: 0.4 | AE9: Y
A10: S116 | B10: MeWP200W STLA-F TRIPUMP0033 | C10: 15.91 | D10: 18.1 | E10: 29.88 | F10: 30.17 | G10: 0.29 | H10: 1.1 | I10: Y | J10: 2.4X4 | K10: 21.06.2023MeWP 80W STLA-F TP EDM 0024 | L10: 11.78 | M10: 17.42 | N10: 25.83 | O10: 26.27 | P10: 0.44 | Q10: 0.88 | R10: Y | S10: 2.4X3 | T10: MeWP 80W STLA EVO BCP0021 | U10: 11.79 | V10: 17.57 | W10: 26.07 | X10: 26.5 | Y10: 0.43 | Z10: 0.66 | AA10: Y | AB10: 2.4X3 | AC10: Y | AD10: 0.483 | AE10: Y

Sheet 11
A3: TR #: | B3: CC23.17608 | G3: Date: | H3: 45166
A4: Program: | B4: Stellantis Coolant Control Module | G4: Technician: | I4: PN/KG(manifold measurement)
A5: Manifold ID | B5: MeWP200 | K5: MeWP80 (EDM) | T5: MeWP80 (BCP) | AC5: 3 Isolators Installed in Correct Direction? | AD5: Leak Test at 1.4bar & 192cc Volume (<0.5cc/min) | AE5: Label Applied ?
B6: ID # | C6: Dist. 1 | D6: Dist. 3 (18.17 ±0.1) | E6: Dist.4 (min) | F6: Dist.4 (max) | G6: Dist. 2 (0.4 ±0.25) | H6: Dist.1+ 15.36-Dist4(max) (1.05±0.5) | I6: O-Ring with P80? | J6: Screws Torque (2.6±0.2Nm) @500rpm | K6: ID # | L6: Dist. 1 | M6: Dist. 3 (17.38 ±0.1) Ref. | N6: Dist.4 (min) | O6: Dist.4 (max) | P6: Dist. 2 (0.4 ±0.25) | Q6: Dist.1+ 15.371-Dist4(max) (0.99±0.5) | R6: O-Ring with P80? | S6: Screws Torque (2.6±0.2Nm) @500rpm | T6: ID # | U6: Dist. 1 | V6: Dist. 3 (17.38±0.1) (Referance) | W6: Dist.4 (min) | X6: Dist.4 (max) | Y6: Dist. 2 (0.4±0.25) | Z6: Dist.1 +15.371 -Dist.4(max) (0.99±0.5) | AA6: O-Ring with P80? | AB6: Screws Torque (2.6±0.2Nm) @500rpm
A7: S201 | B7: MeWP200W STLA-F TRIPUMP0032 | C7: 15.36 | D7: 18.06 | E7: 29.86 | F7: 30.18 | G7: 0.32 | H7: 0.54 | I7: Y | J7: Y | K7: 21.06.2023MeWP 80W STLA-F TP EDM 0018 | L7: 11.37 | M7: 17.43 | N7: 25.84 | O7: 26.26 | P7: 0.42 | Q7: 0.48 | R7: Y | S7: Y | T7: MeWP 80W STLA EVO BCP0023 | U7: 11.12 | V7: 17.51 | W7: 26.04 | X7: 26.47 | Y7: 0.43 | Z7: 0.02 | AA7: Y | AB7: Y | AC7: Y | AD7: 0.466 | AE7: Y
B8: Note: "Dist. 1" measured by Karthik; out of spec value "0.02" in RED approved by Karthik via email; the step at BCP port in manifold was fixed by OG.
B9: MeWP200W STLA-F TRIPUMP0047 | C9: MeWP200 was moved to S120 for shipment on Sep. 18, 2023. New pump assembled on Sep. 19, 2023. | X9: Leak re-test with new GEN pump | AD9: 0.46

Sheet 10
A3: TR #: | B3: CC23.19595 | G3: Date: | H3: 45184
A4: Program: | B4: Stellantis Coolant Control Module | G4: Technician: | I4: PN
A5: Manifold ID | B5: MeWP200 | K5: MeWP80 (EDM) | T5: MeWP80 (BCP) | AC5: 3 Isolators Installed in Correct Direction? | AD5: Leak Test at 1.4bar & 192cc Volume (<0.5cc/min) | AE5: Label Applied ?
B6: ID # | C6: Dist. 1 | D6: Dist. 3 (18.17 ±0.1) | E6: Dist.4 (min) | F6: Dist.4 (max) | G6: Dist. 2 (0.4 ±0.25) | H6: Dist.1+ 15.36-Dist4(max) (1.05±0.5) | I6: O-Ring with P80? | J6: Screws Torque (2.2±0.2Nm) | K6: ID # | L6: Dist. 1 | M6: Dist. 3 (17.38 ±0.1) Ref. | N6: Dist.4 (min) | O6: Dist.4 (max) | P6: Dist. 2 (0.4 ±0.25) | Q6: Dist.1+ 15.371-Dist4(max) (0.99±0.5) | R6: O-Ring with P80? | S6: Screws Torque (2.2±0.2Nm) | T6: ID # | U6: Dist. 1 | V6: Dist. 3 (17.38±0.1) (Referance) | W6: Dist.4 (min) | X6: Dist.4 (max) | Y6: Dist. 2 (0.4±0.25) | Z6: Dist.1 +15.371 -Dist.4(max) (0.99±0.5) | AA6: O-Ring with P80? | AB6: Screws Torque (2.2±0.2Nm)
A7: S118 | B7: MeWP200W STLA-F TRIPUMP0037 | K7: 21.06.2023MeWP 80W STLA-F TP EDM 0022 | T7: MeWP 80W STLA EVO BCP0020 | AD7: 0.161 | AE7: Y
A8: S119 | B8: MeWP200W STLA-F TRIPUMP0027 | K8: 21.06.2023MeWP 80W STLA-F TP EDM 0021 | T8: MeWP 80W STLA EVO BCP0027 | AD8: 0.178 | AE8: Y
A9: S120 | B9: MeWP200W STLA-F TRIPUMP0039 | K9: 21.06.2023MeWP 80W STLA-F TP EDM 0025 | T9: MeWP 80W STLA EVO BCP0026 | AD9: 0.246 | AE9: Y
B10: S120 MeWP200 pump was replaced with the one from S201 on Sep. 18, 2023

Sheet 9
A5: TR # | C5: CC23.22947 | F5: Date: | H5: 45232
A6: Program: | C6: Stellantis Coolant Control Module | F6: Technician: | H6: JX
A7: Manifold ID | B7: Assembly ID | C7: MeWP200 | J7: MeWP80 (EDM) | Q7: MeWP80 (EVO) | X7: 3 Isolators Installed in Correct Direction? | Y7: Leak Test at 1.4bar & 192cc Volume (<0.5cc/min) | Z7: Label Applied ?
C8: ID # (PLUC431M1D0A-01) SW:B1C0 | D8: O-ring installed? | E8: Dist. 1 | F8: Screws Torque (2.6±0.2Nm @ 500rpm) | J8: ID # (UC431M1D1B-01) SW B530 Aluminum Housing | K8: O-ring Installed? | L8: Dist. 2 | M8: Screws Torque (2.6±0.2Nm) | Q8: ID # (UC431M1D2B-01 SW BC60) Plastic Housing | R8: O-ring Installed? | S8: Dist. 3 | T8: Screws Torque (2.6±0.2Nm)
A9: 1 | B9: S202 | C9: MeWP200W STLA-F TRIPUMP0051 | D9: Y | E9: -0.446 | F9: 2.8/71° 2.58/64° 2.71/69° 2.62/79° | J9: 09.08.2023MeWP 80W STLA-F TP EDM0043 | K9: Y | L9: -0.193 | M9: 2.76/96° 2.86/33° 2.78/59° | Q9: MeWP 80W STLA EVO BCP0033 | R9: Y | S9: -0.091 | T9: 2.63/50° 2.56/208° 2.62/64° | X9: Y | Y9: 0.314 | Z9: Y
A10: 2 | B10: S203 | C10: MeWP200W STLA-F TRIPUMP0050 | D10: Y | E10: -0.396 | F10: 2.67/72° | G10: 2.7/70° | H10: 2.69/70° | I10: 2.71/82° | J10: 09.08.2023MeWP 80W STLA-F TP EDM0042 | K10: Y | L10: -0.107 | M10: 2.67/251° | N10: 2.73/63° | P10: 2.66/80° | Q10: MeWP 80W STLA EVO BCP0032 | R10: Y | S10: 0.034 | T10: 2.61/57° | U10: 2.56/64° | W10: 2.64/258° | X10: Y | Y10: 0.372 | Z10: Y
A11: 12 | B11: S204 | C11: MeWP200W STLA-F TRIPUMP0049 | D11: Y | E11: -0.36 | F11: 2.77/49° | G11: 2.64/53° | H11: 2.65/50° | I11: 2.63/66° | J11: 09.08.2023MeWP 80W STLA-F TP EDM0041 | K11: Y | L11: -0.39 | M11: 2.57/33° | N11: 2.77/55° | P11: 2.82/48° | Q11: MeWP 80W STLA EVO BCP0037 | R11: Y | S11: 0.01 | T11: 2.58/59° | U11: 2.55/204° | W11: 2.55/60° | X11: Y | Y11: 0.348 | Z11: Y
C12: Pumps from S203 & S204 moved to S205 & S206 (Nov. 14, 2023, PN) | Q12: Pumps from S203 & S204 moved to S205 & S206 (Nov. 14, 2023, PN)
A13: 7 | B13: S205 | C13: MeWP200W STLA-F TRIPUMP0050 | D13: Y | E13: N/A | F13: 2.8 | G13: 2.71 | H13: 2.73 | I13: 2.8 | J13: 09.08.2023MeWP 80W STLA-F TP EDM0042 | K13: Y | L13: N/A | M13: 2.8 | N13: 2.8 | P13: 2.74 | Q13: MeWP 80W STLA EVO BCP0032 | R13: Y | S13: N/A | T13: 2.57 | U13: 2.54 | V13: 2.59 | X13: N | Y13: 0.351 | Z13: Y
A14: 19 | B14: S206 | C14: MeWP200W STLA-F TRIPUMP0049 | D14: Y | E14: N/A | F14: 2.8 | G14: 2.72 | H14: 2.67 | I14: 2.72 | J14: 09.08.2023MeWP 80W STLA-F TP EDM0041 | K14: Y | L14: N/A | M14: 2.8 | N14: 2.8 | P14: 2.78 | Q14: MeWP 80W STLA EVO BCP0037 | R14: Y | S14: N/A | T14: 2.59 | U14: 2.63 | V14: 2.61 | X14: N | Y14: 0.384 | Z14: Y

Sheet 8
A5: TR # | C5: CC23.22949 | F5: Date: | H5: 45252
A6: Program: | C6: Stellantis Coolant Control Module | F6: Technician: | H6: PN
A7: Assembly ID | B7: Manifold | D7: MeWP200 | H7: MeWP80 (EDM) | K7: MeWP80 (EVO) | N7: 3 Isolators Installed in Correct Direction? | O7: Leak Test at 1.4bar & 192cc Volume (<0.5cc/min) | P7: Label(s) Applied ?
B8: ID # | C8: Gauge Check (Pass/Fail) | D8: ID # (PLUC431M1D0A-01) SW:B1C0 | E8: O-ring installed? | F8: Screws Torque (2.6±0.2Nm @ 500rpm) | H8: ID # (UC431M1D1B-01) SW B530 Aluminum Housing | I8: O-ring Installed? | J8: Screws Torque (2.6±0.2Nm@500rpm) | K8: ID # (UC431M1D2B-01 SW BC60) Plastic Housing | L8: O-ring Installed? | M8: Screws Torque (2.6±0.2Nm @500rpm)
A9: S207 | B9: 8 | C9: P | D9: MeWP200W STLA-F TRIPUMP0046 | E9: Y | F9: 2.62-2.69 | H9: 09.08.2023MeWP 80W STLA-F TP EDM0038 | I9: Y | J9: 2.68-2.72 | K9: MeWP 80W STLA EVO BCP0039 | L9: Y | M9: 2.60-2.69 | N9: Y | O9: 0.411 | P9: Y
A10: S208 | B10: 11 | C10: P | D10: MeWP200W STLA-F TRIPUMP0041 | E10: Y | F10: 2.61-2.76 | H10: 09.08.2023MeWP 80W STLA-F TP EDM0033 | I10: Y | J10: 2.69-2.76 | K10: MeWP 80W STLA EVO BCP0034 | L10: Y | M10: 2.53-2.60 | N10: Y | O10: 0.433 | P10: Y
A11: S209 | B11: 4 | C11: P | D11: MeWP200W STLA-F TRIPUMP0036 | E11: Y | F11: 2.64-2.70 | H11: 09.08.2023MeWP 80W STLA-F TP EDM0032 | I11: Y | J11: 2.67-2.79 | K11: MeWP 80W STLA EVO BCP0044 | L11: Y | M11: 2.56-2.60 | N11: Y | O11: 0.362 | P11: Y
A12: S210 | B12: 14 | C12: P | D12: MeWP200W STLA-F TRIPUMP0045 | E12: Y | F12: 2.69-2.80 | H12: 09.08.2023MeWP 80W STLA-F TP EDM0037 | I12: Y | J12: 2.64-2.77 | K12: MeWP 80W STLA EVO BCP0038 | L12: Y | M12: 2.57-2.62 | N12: Y | O12: 0.405 | P12: Y

Sheet 7
A5: TR # | C5: CC23.22950 | F5: Date: | H5: 45295
A6: Program: | C6: Stellantis Coolant Control Module | F6: Technician: | H6: PN/JX
A7: Assembly ID | B7: Manifold | D7: MeWP200 | H7: MeWP80 (EDM) | K7: MeWP80 (EVO) | N7: 3 Isolators Installed in Correct Direction? | O7: Leak Test at 1.4bar & 192cc Volume (<0.5cc/min) | P7: Label(s) Applied ?
B8: ID # | C8: Gauge Check (Pass/Fail) | D8: ID # (PLUC431M1D0A-01) SW:B1C0 | E8: O-ring installed? | F8: Screws Torque (2.6±0.2Nm @ 500rpm) | H8: ID # (UC431M1D1B-01) SW B530 Aluminum Housing | I8: O-ring Installed? | J8: Screws Torque (2.6±0.2Nm@500rpm) | K8: ID # (UC431M1D2B-01 SW BC60) Plastic Housing | L8: O-ring Installed? | M8: Screws Torque (2.6±0.2Nm @500rpm)
A9: S212 | B9: 1 | C9: P | D9: 034 | E9: Y | F9: 2.50~2.61 | H9: 031 | I9: Y | J9: 2.51~2.67 | K9: 45 | L9: Y | M9: 2.50~2.63 | N9: N/A | O9: 0.475 | P9: Y
A10: S213 | B10: 2 | C10: P | D10: MeWP200W STLA-F TRIPUMP0065 | E10: Y | F10: 2.59~2.69 | H10: 15.12.2023MeWP 80W STLA-F TP EDM0062 | I10: Y | J10: 2.62~2.72 | K10: MeWP 80W STLA EVO BCP0075 | L10: Y | M10: 2.55~2.60 | N10: Y | O10: 0.072 | P10: Y
A11: S214 | B11: 3 | C11: P | D11: MeWP200W STLA-F TRIPUMP0066 | E11: Y | F11: 2.58~2.74 | H11: 15.12.2023MeWP 80W STLA-F TP EDM0063 | I11: Y | J11: 2.53~2.72 | K11: MeWP 80W STLA EVO BCP0076 | L11: Y | M11: 2.55~2.60 | N11: Y | O11: 0.07 | P11: Y
A12: S215 | B12: 4 | C12: P | D12: MeWP200W STLA-F TRIPUMP0068 | E12: Y | F12: 2.55~2.69 | H12: 15.12.2023MeWP 80W STLA-F TP EDM0068 | I12: Y | J12: 2.65~2.74 | K12: MeWP 80W STLA EVO BCP0078 | L12: Y | M12: 2.56~2.64 | N12: Y | O12: 0.337 | P12: Y
A13: reworked S212 | B13: 1 | C13: P | D13: MeWP200W STLA-F TRIPUMP0067 | E13: Y | F13: 2.50~2.68 | H13: 15.12.2023MeWP 80W STLA-F TP EDM0067 | I13: Y | J13: 2.61~2.72 | K13: MeWP 80W STLA EVO BCP0077 | L13: Y | M13: 2.53~2.61 | N13: Y | O13: 0.333 | P13: Y
A14: S216 | B14: 1 | C14: P | D14: MeWP200W STLA-F TRIPUMP0080 | E14: Y | F14: 2.58~2.63 | H14: 15.12.2023MeWP 80W STLA-F TP EDM0071 | I14: Y | J14: 2.59~2.75 | K14: MeWP 80W STLA EVO BCP0070 | L14: Y | M14: 2.56~2.63 | N14: Y | O14: 0.41 | P14: Y

Sheet 6
A5: TR # | C5: CC24.01600 | F5: Date: | H5: 45314
A6: Program: | C6: Stellantis Coolant Control Module | F6: Technician: | H6: PN
A7: Assembly ID | B7: Manifold | D7: MeWP200 | H7: MeWP80 (EDM) | K7: MeWP80 (EVO) | N7: 3 Isolators Installed in Correct Direction? | O7: Leak Test at 1.4bar & 192cc Volume (<0.5cc/min) | P7: Label(s) Applied ?
B8: ID # | C8: Gauge Check (Pass/Fail) | D8: ID # (PLUC431M1D0A-01) SW:B1C0 | E8: O-ring installed? | F8: Screws Torque (2.6±0.2Nm @ 500rpm) | H8: ID # (UC431M1D1B-01) SW B530 Aluminum Housing | I8: O-ring Installed? | J8: Screws Torque (2.6±0.2Nm@500rpm) | K8: ID # (UC431M1D2B-01 SW BC60) Plastic Housing | L8: O-ring Installed? | M8: Screws Torque (2.6±0.2Nm @500rpm)
A9: S217 | B9: 2 | C9: F (0.11mm Max) | D9: MeWP200W STLA-F TRIPUMP0074 | E9: Y | F9: 2.57~2.69 | H9: 15.12.2023MeWP 80W STLA-F TP EDM0061 | I9: Y | J9: 2.72~2.74 | K9: MeWP 80W STLA EVO BCP0069 | L9: Y | M9: 2.53~2.63 | N9: Y | O9: 0.34 | P9: Y
A10: S218 | B10: 3 | C10: F (0.108mm Max) | D10: MeWP200W STLA-F TRIPUMP0061 | E10: Y | F10: 2.62~2.71 | H10: 15.12.2023MeWP 80W STLA-F TP EDM0065 | I10: Y | J10: 2.64~2.74 | K10: MeWP 80W STLA EVO BCP0064 | L10: Y | M10: 2.59~2.71 | N10: Y | O10: 0.315 | P10: Y
A11: S219 | B11: 4 | C11: P | D11: MeWP200W STLA-F TRIPUMP0081 | E11: Y | F11: 2.63~2.74 | H11: 15.12.2023MeWP 80W STLA-F TP EDM0070 | I11: Y | J11: 2.71~2.80 | K11: MeWP 80W STLA EVO BCP0060 | L11: Y | M11: 2.53~2.65 | N11: Y | O11: 0.308 | P11: Y
A12: S220 | B12: 8 | C12: Fail 0.08 max | D12: MeWP200W STLA-F TRIPUMP0064 | E12: Y | F12: 2.63~2.71 | H12: 15.12.2023MeWP 80W STLA-F TP EDM0064 | I12: Y | J12: 2.71~2.80 | K12: MeWP 80W STLA EVO BCP0063 | L12: Y | M12: 2.57~2.63 | N12: Y | O12: 0.394 | P12: Y
A13: S221 | B13: 10 | C13: Fail 0.04 max | D13: MeWP200W STLA-F TRIPUMP0082 | E13: Y | F13: 2.57~2.69 | H13: 15.12.2023MeWP 80W STLA-F TP EDM0078 | I13: Y | J13: 2.59~2.69 | K13: MeWP 80W STLA EVO BCP0074 | L13: Y | M13: 2.53~2.57 | N13: Y | O13: 0.299 | P13: Y

Sheet 5
A5: TR # | C5: CC24.02109 | F5: Date: | G5: 45316
A6: Program: | C6: Stellantis Coolant Control Module | F6: Technician: | G6: JX
A7: Assembly ID | B7: Manifold | D7: MeWP200 | G7: MeWP80 (EDM) | J7: MeWP80 (EVO) | M7: 3 Isolators Installed in Correct Direction? | N7: Leak Test at 1.4bar & 192cc Volume (<0.5cc/min) | O7: Label(s) Applied ?
B8: ID # | C8: Gauge Check (Pass/Fail) | D8: ID # (PLUC431M1D0A-01) SW:B1C0 | E8: O-ring installed? | F8: Screws Torque (2.6±0.2Nm @ 500rpm) | G8: ID # (UC431M1D1B-01) SW B530 Aluminum Housing | H8: O-ring Installed? | I8: Screws Torque (2.6±0.2Nm@500rpm) | J8: ID # (UC431M1D2B-01 SW BC60) Plastic Housing | K8: O-ring Installed? | L8: Screws Torque (2.6±0.2Nm @500rpm)
A9: S222 | B9: 11 | C9: FAILED MAX 0.114MM | D9: MeWP200W STLA-F TRIPUMP0071 | E9: Y | F9: 2.55-2.72 | G9: 15.12.2023MeWP 80W STLA-F TP EDM0069 | H9: Y | I9: 2.62-2.71 | J9: MeWP 80W STLA EVO BCP0061 | K9: Y | L9: 2.54-2.58 | M9: Y | N9: 0.412 | O9: Y
A10: S223 | B10: 12 | C10: FAILED MAX 0.124MM | D10: MeWP200W STLA-F TRIPUMP0073 | E10: Y | F10: 2.56-2.70 | G10: 15.12.2023MeWP 80W STLA-F TP EDM0072 | H10: Y | I10: 2.63-2.73 | J10: MeWP 80W STLA EVO BCP0065 | K10: Y | L10: 2.56-2.62 | M10: Y | N10: 0.359 | O10: Y
A11: S224 | B11: 13 | C11: FAILED MAX 0.147MM | D11: MeWP200W STLA-F TRIPUMP0075 | E11: Y | F11: 2.55-2.75 | G11: 15.12.2023MeWP 80W STLA-F TP EDM0074 | H11: Y | I11: 2.64-2.80 | J11: MeWP 80W STLA EVO BCP0066 | K11: Y | L11: 2.64-2.80 | M11: Y | N11: 0.304 | O11: Y
A12: S225 | B12: 14 | C12: FAILED MAX 0.097MM | D12: MeWP200W STLA-F TRIPUMP0076 | E12: Y | F12: 2.56-2.69 | G12: 15.12.2023MeWP 80W STLA-F TP EDM0076 | H12: Y | I12: 2.59-2.71 | J12: MeWP 80W STLA EVO BCP0079 | K12: Y | L12: 2.59-2.71 | M12: Y | N12: 0.304 | O12: Y
A13: S226 | B13: 15 | C13: FAILED 0.030MM | D13: MeWP200W STLA-F TRIPUMP0098 | E13: Y | F13: 2.55-2.63 | G13: 10.01.2024MeWP 80W STLA-F TP EDM0106 | H13: Y | I13: 2.66-2.72 | J13: MeWP 80W STLA EVO BCP0081 | K13: Y | L13: 2.50-2.66 | M13: Y | N13: 0.454 | O13: Y

Sheet 4
A5: TR # | C5: CC24.02734 | F5: Date: | G5: 45329
A6: Program: | C6: Stellantis Coolant Control Module | F6: Technician: | G6: PN
A7: Assembly ID | B7: Manifold | D7: MeWP200 | G7: MeWP80 (EDM) | J7: MeWP80 (EVO) | M7: 3 Isolators Installed in Correct Direction? | N7: Leak Test at 1.4bar & 192cc Volume (<0.5cc/min) | O7: Label(s) Applied ?
B8: ID # | C8: Gauge Check (Pass/Fail) | D8: ID # (PLUC431M1D0A-01) SW:B1C1 | E8: O-ring installed? | F8: Screws Torque (2.6±0.2Nm @500rpm) | G8: ID # (UC431M1D1B-01) SW B530 Aluminum Housing | H8: O-ring Installed? | I8: Screws Torque (2.6±0.2Nm @500rpm) | J8: ID # (UC431M1D2B-01 SW BC60) Plastic Housing | K8: O-ring Installed? | L8: Screws Torque (2.6±0.2Nm @500rpm)
A9: S227 | B9: 16 | C9: F 0.02 | D9: MeWP200W STLA-F TRIPUMP0123 | E9: Y | F9: 2.60~2.65 | G9: 23.01.2024MeWP 80W STLA-F TP EDM0120 | H9: Y | I9: 2.68~2.77 | J9: MeWP 80W STLA EVO BCP0101 | K9: Y | L9: 2.54~2.62 | M9: Y | N9: 0.396 | O9: Y
A10: S228 | B10: 17 | C10: P | D10: MeWP200W STLA-F TRIPUMP0093 | E10: Y | F10: 2.62~2.68 | G10: 10.01.2024MeWP 80W STLA-F TP EDM0107 | H10: Y | I10: 2.64~2.77 | J10: MeWP 80W STLA EVO BCP0098 | K10: Y | L10: 2.55~2.64 | M10: Y | N10: 0.417 | O10: Y
A11: S229 | B11: 18 | C11: F 0.04 | D11: MeWP200W STLA-F TRIPUMP0119 | E11: Y | F11: 2.61~2.69 | G11: 10.01.2024MeWP 80W STLA-F TP EDM0108 | H11: Y | I11: 2.69~2.75 | J11: MeWP 80W STLA EVO BCP0092 | K11: Y | L11: 2.57~2.64 | M11: Y | N11: 0.404 | O11: Y
A12: S230 | B12: 19 | C12: F 0.07 | D12: MeWP200W STLA-F TRIPUMP0099 | E12: Y | F12: 2.58~2.67 | G12: 23.01.2024MeWP 80W STLA-F TP EDM0119 | H12: Y | I12: 2.68~2.75 | J12: MeWP 80W STLA EVO BCP0080 | K12: Y | L12: 2.55~2.62 | M12: Y | N12: 0.425 | O12: Y
A13: S231 | B13: 20 | C13: F 0.1 | D13: MeWP200W STLA-F TRIPUMP0120 | E13: Y | F13: 2.58~2.68 | G13: 10.01.2024MeWP 80W STLA-F TP EDM0084 | H13: Y | I13: 2.70~2.80 | J13: MeWP 80W STLA EVO BCP0090 | K13: Y | L13: 2.56~2.65 | M13: Y | N13: 0.341 | O13: Y
A14: S232 | B14: 21 | C14: F 0.05 | D14: MeWP200W STLA-F TRIPUMP0101 | E14: Y | F14: 2.62~2.72 | G14: 10.01.2024MeWP 80W STLA-F TP EDM0105 | H14: Y | I14: 2.71~2.76 | J14: MeWP 80W STLA EVO BCP0106 | K14: Y | L14: 2.63~2.67 | M14: Y | N14: 0.33 | O14: Y
A15: S233 | B15: 22 | C15: F 0.02 | D15: MeWP200W STLA-F TRIPUMP0096 | E15: Y | F15: 2.61~2.69 | G15: 23.01.2024MeWP 80W STLA-F TP EDM0113 | H15: Y | I15: 2.64~2.75 | J15: MeWP 80W STLA EVO BCP0116 | K15: Y | L15: 2.55~2.62 | M15: Y | N15: 0.299 | O15: Y
A16: S234 | B16: 23 | C16: P | D16: MeWP200W STLA-F TRIPUMP0085 | E16: Y | F16: 2.57~2.68 | G16: 10.01.2024MeWP 80W STLA-F TP EDM0083 | H16: Y | I16: 2.74~2.80 | J16: MeWP 80W STLA EVO BCP0096 | K16: Y | L16: 2.54~2.62 | M16: Y | N16: 0.351 | O16: Y
